<?xml version="1.0" encoding="UTF-8"?>
<!-- Generated by org.testng.reporters.JUnitReportReporter -->
<testsuite hostname="DESKTOP-6M54JAQ" failures="3" tests="16" name="testcase.Login" time="125.745" errors="0" timestamp="2024-09-15T00:12:56 IST" skipped="0">
  <testcase classname="testcase.Login" name="validation_for_invalid_PhEmail" time="3.989"/>
  <system-out/>
  <testcase classname="testcase.Login" name="validation_for_empty_pass" time="4.848"/>
  <system-out/>
  <testcase classname="testcase.Login" name="login" time="29.017">
    <failure message="The following asserts failed:
	expected [https://demo.workorbits.com/dashboard/ongoing1] but found [https://demo.workorbits.com/dashboard/ongoing]" type="java.lang.AssertionError">
      <![CDATA[java.lang.AssertionError: The following asserts failed:
expected [https://demo.workorbits.com/dashboard/ongoing1] but found [https://demo.workorbits.com/dashboard/ongoing]
at org.testng.asserts.SoftAssert.assertAll(SoftAssert.java:47)
at org.testng.asserts.SoftAssert.assertAll(SoftAssert.java:31)
at testcase.Login.login(Login.java:63)
at java.base/jdk.internal.reflect.DirectMethodHandleAccessor.invoke(DirectMethodHandleAccessor.java:103)
at java.base/java.lang.reflect.Method.invoke(Method.java:580)
at org.testng.internal.MethodInvocationHelper.invokeMethod(MethodInvocationHelper.java:133)
at org.testng.internal.TestInvoker.invokeMethod(TestInvoker.java:598)
at org.testng.internal.TestInvoker.invokeTestMethod(TestInvoker.java:173)
at org.testng.internal.MethodRunner.runInSequence(MethodRunner.java:46)
at org.testng.internal.TestInvoker$MethodInvocationAgent.invoke(TestInvoker.java:824)
at org.testng.internal.TestInvoker.invokeTestMethods(TestInvoker.java:146)
at org.testng.internal.TestMethodWorker.invokeTestMethods(TestMethodWorker.java:146)
at org.testng.internal.TestMethodWorker.run(TestMethodWorker.java:128)
at java.base/java.util.ArrayList.forEach(ArrayList.java:1597)
at org.testng.TestRunner.privateRun(TestRunner.java:794)
at org.testng.TestRunner.run(TestRunner.java:596)
at org.testng.SuiteRunner.runTest(SuiteRunner.java:377)
at org.testng.SuiteRunner.runSequentially(SuiteRunner.java:371)
at org.testng.SuiteRunner.privateRun(SuiteRunner.java:332)
at org.testng.SuiteRunner.run(SuiteRunner.java:276)
at org.testng.SuiteRunnerWorker.runSuite(SuiteRunnerWorker.java:53)
at org.testng.SuiteRunnerWorker.run(SuiteRunnerWorker.java:96)
at org.testng.TestNG.runSuitesSequentially(TestNG.java:1212)
at org.testng.TestNG.runSuitesLocally(TestNG.java:1134)
at org.testng.TestNG.runSuites(TestNG.java:1063)
at org.testng.TestNG.run(TestNG.java:1031)
at org.testng.remote.AbstractRemoteTestNG.run(AbstractRemoteTestNG.java:115)
at org.testng.remote.RemoteTestNG.initAndRun(RemoteTestNG.java:293)
at org.testng.remote.RemoteTestNG.main(RemoteTestNG.java:91)
]]>
    </failure>
  </testcase> <!-- login -->
  <system-out/>
  <testcase classname="testcase.Login" name="validation_For_empty_emailPhone" time="5.341"/>
  <system-out/>
  <testcase classname="testcase.Login" name="validation_for_invalid_PhEmail" time="4.543"/>
  <system-out/>
  <testcase classname="testcase.Login" name="validation_On_Empty_NewPassword" time="8.715"/>
  <system-out/>
  <testcase classname="testcase.Login" name="validation_On_Empty_OTP" time="8.473">
    <failure message="The following asserts failed:
	expected [An error has occurred! Validation failed for Verify-Reset-Password. Must not be empty.] but found [An error has occurred! Validation failed for Verify-Reset-Password . - must not be null]" type="java.lang.AssertionError">
      <![CDATA[java.lang.AssertionError: The following asserts failed:
expected [An error has occurred! Validation failed for Verify-Reset-Password. Must not be empty.] but found [An error has occurred! Validation failed for Verify-Reset-Password . - must not be null]
at org.testng.asserts.SoftAssert.assertAll(SoftAssert.java:47)
at org.testng.asserts.SoftAssert.assertAll(SoftAssert.java:31)
at testcase.Login.validation_On_Empty_OTP(Login.java:328)
at java.base/jdk.internal.reflect.DirectMethodHandleAccessor.invoke(DirectMethodHandleAccessor.java:103)
at java.base/java.lang.reflect.Method.invoke(Method.java:580)
at org.testng.internal.MethodInvocationHelper.invokeMethod(MethodInvocationHelper.java:133)
at org.testng.internal.TestInvoker.invokeMethod(TestInvoker.java:598)
at org.testng.internal.TestInvoker.invokeTestMethod(TestInvoker.java:173)
at org.testng.internal.MethodRunner.runInSequence(MethodRunner.java:46)
at org.testng.internal.TestInvoker$MethodInvocationAgent.invoke(TestInvoker.java:824)
at org.testng.internal.TestInvoker.invokeTestMethods(TestInvoker.java:146)
at org.testng.internal.TestMethodWorker.invokeTestMethods(TestMethodWorker.java:146)
at org.testng.internal.TestMethodWorker.run(TestMethodWorker.java:128)
at java.base/java.util.ArrayList.forEach(ArrayList.java:1597)
at org.testng.TestRunner.privateRun(TestRunner.java:794)
at org.testng.TestRunner.run(TestRunner.java:596)
at org.testng.SuiteRunner.runTest(SuiteRunner.java:377)
at org.testng.SuiteRunner.runSequentially(SuiteRunner.java:371)
at org.testng.SuiteRunner.privateRun(SuiteRunner.java:332)
at org.testng.SuiteRunner.run(SuiteRunner.java:276)
at org.testng.SuiteRunnerWorker.runSuite(SuiteRunnerWorker.java:53)
at org.testng.SuiteRunnerWorker.run(SuiteRunnerWorker.java:96)
at org.testng.TestNG.runSuitesSequentially(TestNG.java:1212)
at org.testng.TestNG.runSuitesLocally(TestNG.java:1134)
at org.testng.TestNG.runSuites(TestNG.java:1063)
at org.testng.TestNG.run(TestNG.java:1031)
at org.testng.remote.AbstractRemoteTestNG.run(AbstractRemoteTestNG.java:115)
at org.testng.remote.RemoteTestNG.initAndRun(RemoteTestNG.java:293)
at org.testng.remote.RemoteTestNG.main(RemoteTestNG.java:91)
]]>
    </failure>
  </testcase> <!-- validation_On_Empty_OTP -->
  <system-out/>
  <testcase classname="testcase.Login" name="forgot_pass_with_valid_email" time="9.343"/>
  <system-out/>
  <testcase classname="testcase.Login" name="validation_On_EmptyEmailPh" time="8.547"/>
  <system-out/>
  <testcase classname="testcase.Login" name="validation_for_invalid_PhEmail" time="4.634"/>
  <system-out/>
  <testcase classname="testcase.Login" name="validation_for_invalid_PhEmail" time="4.679"/>
  <system-out/>
  <testcase classname="testcase.Login" name="validation_for_invalid_PhEmail" time="4.778"/>
  <system-out/>
  <testcase classname="testcase.Login" name="validation_On_NewPassword" time="6.520">
    <failure message="The following asserts failed:
	expected [An error has occurred! Validation failed for Verify-Reset-Password. Must not be empty. Size must be between 6 and 2147483647] but found [An error has occurred! Validation failed for Verify-Reset-Password . - size must be between 6 and 2147483647]" type="java.lang.AssertionError">
      <![CDATA[java.lang.AssertionError: The following asserts failed:
expected [An error has occurred! Validation failed for Verify-Reset-Password. Must not be empty. Size must be between 6 and 2147483647] but found [An error has occurred! Validation failed for Verify-Reset-Password . - size must be between 6 and 2147483647]
at org.testng.asserts.SoftAssert.assertAll(SoftAssert.java:47)
at org.testng.asserts.SoftAssert.assertAll(SoftAssert.java:31)
at testcase.Login.validation_On_NewPassword(Login.java:419)
at java.base/jdk.internal.reflect.DirectMethodHandleAccessor.invoke(DirectMethodHandleAccessor.java:103)
at java.base/java.lang.reflect.Method.invoke(Method.java:580)
at org.testng.internal.MethodInvocationHelper.invokeMethod(MethodInvocationHelper.java:133)
at org.testng.internal.TestInvoker.invokeMethod(TestInvoker.java:598)
at org.testng.internal.TestInvoker.invokeTestMethod(TestInvoker.java:173)
at org.testng.internal.MethodRunner.runInSequence(MethodRunner.java:46)
at org.testng.internal.TestInvoker$MethodInvocationAgent.invoke(TestInvoker.java:824)
at org.testng.internal.TestInvoker.invokeTestMethods(TestInvoker.java:146)
at org.testng.internal.TestMethodWorker.invokeTestMethods(TestMethodWorker.java:146)
at org.testng.internal.TestMethodWorker.run(TestMethodWorker.java:128)
at java.base/java.util.ArrayList.forEach(ArrayList.java:1597)
at org.testng.TestRunner.privateRun(TestRunner.java:794)
at org.testng.TestRunner.run(TestRunner.java:596)
at org.testng.SuiteRunner.runTest(SuiteRunner.java:377)
at org.testng.SuiteRunner.runSequentially(SuiteRunner.java:371)
at org.testng.SuiteRunner.privateRun(SuiteRunner.java:332)
at org.testng.SuiteRunner.run(SuiteRunner.java:276)
at org.testng.SuiteRunnerWorker.runSuite(SuiteRunnerWorker.java:53)
at org.testng.SuiteRunnerWorker.run(SuiteRunnerWorker.java:96)
at org.testng.TestNG.runSuitesSequentially(TestNG.java:1212)
at org.testng.TestNG.runSuitesLocally(TestNG.java:1134)
at org.testng.TestNG.runSuites(TestNG.java:1063)
at org.testng.TestNG.run(TestNG.java:1031)
at org.testng.remote.AbstractRemoteTestNG.run(AbstractRemoteTestNG.java:115)
at org.testng.remote.RemoteTestNG.initAndRun(RemoteTestNG.java:293)
at org.testng.remote.RemoteTestNG.main(RemoteTestNG.java:91)
]]>
    </failure>
  </testcase> <!-- validation_On_NewPassword -->
  <system-out/>
  <testcase classname="testcase.Login" name="validation_On_InvalidPassword" time="5.444"/>
  <system-out/>
  <testcase classname="testcase.Login" name="login_with_valid_phNum_pass" time="5.425"/>
  <system-out/>
  <testcase classname="testcase.Login" name="login_with_valid_email_and_pass" time="11.449"/>
  <system-out/>
</testsuite> <!-- testcase.Login -->
